{"componentChunkName":"component---src-templates-category-template-js","path":"/category/python-view-try-exception","result":{"data":{"allMarkdownRemark":{"edges":[{"node":{"fields":{"categorySlug":"/category/python-view-try-exception/","slug":"/posts/django-part10/"},"frontmatter":{"date":"2019-12-11T23:30:03.284Z","description":"Views Try-Except & django give exceptions","category":"Python/View/Try/Exception/","title":"Django View part3"}}}]}},"pageContext":{"isCreatedByStatefulCreatePages":false,"category":"Python/View/Try/Exception/","currentPage":0,"postsLimit":4,"postsOffset":0,"prevPagePath":"/category/python-view-try-exception","nextPagePath":"/category/python-view-try-exception/page/1","hasPrevPage":false,"hasNextPage":false}}}